<sdf version='1.5'>


  <model name='autogyro'>
   <pose>0 0 0.2 0 0 0</pose>
    <link name='base_link'>
      <pose>0 0 0 0 0 0</pose>
      <inertial>
        <pose>0.05 0 0.05 0 0 0</pose>
        <mass>4.9</mass>
        <inertia>
          <ixx>1</ixx>
          <ixy>0</ixy>
          <ixz>0</ixz>
          <iyy>1</iyy>
          <iyz>0</iyz>
          <izz>1</izz>
        </inertia>
      </inertial>
      <collision name='base_link_collision'>
        <!--dummy  body collision-->
        <pose>0 0 0 0 0 0</pose>
        <geometry>
          <box>
            <size>0.1 0.1 0.1</size>
          </box>
        </geometry>
        <surface>
          <friction>
            <ode>
              <mu>0.1</mu>
              <mu2>0.1</mu2>
            </ode>
          </friction>
          <contact>
            <ode>
              <min_depth>0.001</min_depth>
              <kp>1e10</kp>
            </ode>
          </contact>
        </surface>
      </collision>

      <visual name='base_link_visual'>
        <pose>0.22 0 0.07 1.5708 0 3.1416</pose>
        <geometry>
          <mesh>
            <scale>0.001 0.001 0.001</scale>
            <uri>model://autogyro/meshes/TF-G1-sim-body.dae</uri>
          </mesh>
        </geometry>
        <material>
          <script>
            <name>Gazebo/Yellow</name>
            <uri>__default__</uri>
          </script>
        </material>
      </visual>
      <self_collide>0</self_collide>
       <visual name='center_visual'>
         <pose>0 0 0 0 0 0</pose>
         <geometry>
           <sphere>
             <radius>0.02</radius>
           </sphere>
         </geometry>
       </visual>
    </link>
    <link name='imu_link'>
      <pose>0 0 0 0 0 0</pose>
      <inertial>
        <pose>0 0 0 0 0 0</pose>
        <mass>0.1</mass>
        <inertia>
          <ixx>0.0001</ixx>
          <ixy>0</ixy>
          <ixz>0</ixz>
          <iyy>0.0001</iyy>
          <iyz>0</iyz>
          <izz>0.0001</izz>
        </inertia>
      </inertial>
    </link>
    <plugin name="slow" filename="libgazebo_slow_plugin.so">
	      <base_link>base_link</base_link>
	      <coef>3</coef>
    </plugin>

    <joint name='imu_joint' type='revolute'>
      <child>imu_link</child>
      <parent>base_link</parent>
      <axis>
        <xyz>1 0 0</xyz>
        <limit>
          <lower>0</lower>
          <upper>0</upper>
          <effort>0</effort>
          <velocity>0</velocity>
        </limit>
        <dynamics>
          <spring_reference>0</spring_reference>
          <spring_stiffness>0</spring_stiffness>
        </dynamics>
        <use_parent_model_frame>1</use_parent_model_frame>
      </axis>
    </joint>

<!--==================================================WHEELS================================================================-->
	<include>
          <uri>model://autogyro/wheel</uri>
		  <name>center_front_wheel</name>
          <pose> 0.5 0.0 -0.095 1.5707 1.5707</pose> 
    </include>

	<include>
          <uri>model://autogyro/wheel</uri>
		  <name>left_rear_wheel</name>
          <pose> -0.22 0.5 -0.095 1.5707 1.5707</pose>  
    </include>

	<include>
          <uri>model://autogyro/wheel</uri>
		  <name>right_rear_wheel</name>
          <pose> -0.22 -0.5 -0.095 1.5707 1.5707</pose>  
    </include>
  
    <joint name="center_front_wheel_joint" type="revolute">
      <pose>0 0 0 0 0 0 </pose>
      <child>center_front_wheel::wheel_link</child>
      <parent>base_link</parent>
      <axis>
        <xyz>0 1 0</xyz>
        <use_parent_model_frame>1</use_parent_model_frame>
      </axis>
      <physics>
        <ode>
          <!--<cfm_damping>1</cfm_damping>-->
          <limit>
            <cfm>0.000000</cfm>
            <erp>0.800000</erp>
          </limit>
        </ode>
      </physics>
    </joint>



    <joint name="left_rear_wheel_joint" type="revolute">
      <pose>0 0 0 0 0 0 </pose>
      <child>left_rear_wheel::wheel_link</child>
      <parent>base_link</parent>
      <axis>
        <xyz>0 1 0</xyz>
        <use_parent_model_frame>1</use_parent_model_frame>
      </axis>
      <physics>
        <ode>
          <!--<cfm_damping>1</cfm_damping>-->
          <limit>
            <cfm>0.000000</cfm>
            <erp>0.800000</erp>
          </limit>
        </ode>
      </physics>
    </joint>

    <joint name="right_rear_wheel_joint" type="revolute">
      <pose>0 0 0 0 0 0 </pose>
      <child>right_rear_wheel::wheel_link</child>
      <parent>base_link</parent>
      <axis>
        <xyz>0 1 0</xyz>
        <use_parent_model_frame>1</use_parent_model_frame>
      </axis>
      <physics>
        <ode>
          <!--<cfm_damping>1</cfm_damping>-->
          <limit>
            <cfm>0.000000</cfm>
            <erp>0.800000</erp>
          </limit>
        </ode>
      </physics>
    </joint>

<!--=================================================== OCAS ===================================================================-->


     <link name="left_rudder">
      <pose>-0.744 0.15 0.07 0 0 0 </pose>
      <inertial>
        <mass>0.006</mass>
        <inertia>
          <ixx>0.00001</ixx>
          <ixy>0.0</ixy>
          <iyy>0.00001</iyy>
          <ixz>0.0</ixz>
          <iyz>0.0</iyz>
          <izz>0.00001</izz>
        </inertia>
      </inertial>
       <visual name="left_rudder_visual">
        <geometry>
          <box>
            <size>0.05 0.01 0.09</size>
          </box>
        </geometry>
        <material>
          <script>
            <name>Gazebo/Purple</name>
            <uri>__default__</uri>
          </script>
        </material>
      </visual>
    </link>

    <link name="right_rudder">
      <pose>-0.744 -0.15 0.07 0 0 0 </pose>
      <inertial>
        <mass>0.006</mass>
        <inertia>
          <ixx>0.00001</ixx>
          <ixy>0.0</ixy>
          <iyy>0.00001</iyy>
          <ixz>0.0</ixz>
          <iyz>0.0</iyz>
          <izz>0.00001</izz>
        </inertia>
      </inertial>
       <visual name="right_rudder_visual">
        <geometry>
          <box>
            <size>0.05 0.01 0.09</size>
          </box>
        </geometry>
      </visual>
    </link>

    <joint name="left_rudder_joint" type="revolute">
      <parent>base_link</parent>
      <child>left_rudder</child>
      <pose>0.025 0 0 0 0 0</pose>
      <axis>
        <xyz>0 0 1</xyz>
        <limit>
          <lower>-0.53</lower>
          <upper>0.53</upper>
        </limit>
        <dynamics>
          <damping>1.000</damping>
        </dynamics>
      </axis>
      <physics>
        <ode>
          <implicit_spring_damper>1</implicit_spring_damper>
        </ode>
      </physics>
    </joint>
    <joint name="right_rudder_joint" type="revolute">
      <parent>base_link</parent>
      <child>right_rudder</child>
      <pose>0.025 0 0 0 0 0</pose>
      <axis>
        <xyz>0 0 1</xyz>
        <limit>
          <lower>-0.53</lower>
          <upper>0.53</upper>
        </limit>
        <dynamics>
          <damping>1.000</damping>
        </dynamics>
      </axis>
      <physics>
        <ode>
          <implicit_spring_damper>1</implicit_spring_damper>
        </ode>
      </physics>
    </joint>

    <plugin name="elevator" filename="libLiftDragPlugin.so">
      <a0>-0.2</a0>
      <cla>4.752798721</cla>
      <cda>0.6417112299</cda>
      <cma>-1.8</cma>
      <alpha_stall>0.3391428111</alpha_stall>
      <cla_stall>-3.85</cla_stall>
      <cda_stall>-0.9233984055</cda_stall>
      <cma_stall>0</cma_stall>
      <cp>-0.8 0 0</cp>
      <area>0.06</area>
      <air_density>1.2041</air_density>
      <forward>1 0 0</forward>
      <upward>0 0 1</upward>
      <link_name>base_link</link_name>
    </plugin>
    <plugin name="leftrudder" filename="libLiftDragPlugin.so">
      <a0>0.0</a0>
      <cla>4.752798721</cla>
      <cda>0.6417112299</cda>
      <cma>-1.8</cma>
      <alpha_stall>0.3391428111</alpha_stall>
      <cla_stall>-3.85</cla_stall>
      <cda_stall>-0.9233984055</cda_stall>
      <cma_stall>0</cma_stall>
      <cp>-0.8 -0.15 0.00</cp>
      <area>0.01</area>
      <air_density>1.2041</air_density>
      <forward>1 0 0</forward>
      <upward>0 -1 0</upward>
      <link_name>base_link</link_name>
      <control_joint_name>
        left_rudder_joint
      </control_joint_name>
      <control_joint_rad_to_cl>-4.0</control_joint_rad_to_cl>
    </plugin>
    <plugin name="rightrudder" filename="libLiftDragPlugin.so">
      <a0>0.0</a0>
      <cla>4.752798721</cla>
      <cda>0.6417112299</cda>
      <cma>-1.8</cma>
      <alpha_stall>0.3391428111</alpha_stall>
      <cla_stall>-3.85</cla_stall>
      <cda_stall>-0.9233984055</cda_stall>
      <cma_stall>0</cma_stall>
      <cp>-0.8 -0.15 0.00</cp>
      <area>0.01</area>
      <air_density>1.2041</air_density>
      <forward>1 0 0</forward>
      <upward>0 1 0</upward>
      <link_name>base_link</link_name>
      <control_joint_name>
        right_rudder_joint
      </control_joint_name>
      <control_joint_rad_to_cl>4.0</control_joint_rad_to_cl>
    </plugin>


<!--============================================================== VRTULE ==================================================-->
    <joint name='propeller_joint' type='revolute'>
      <child>propeller</child>
      <parent>base_link</parent>
      <axis>
        <xyz>0.99 0 -0.1</xyz>
      </axis>
    </joint>

    <link name='propeller'>
      <pose>0.23 0 0.063 0 1.6714649789527254 0</pose>
      <inertial>
        <pose>0 0 0 0 0 0</pose>
        <mass>0.01</mass>
        <inertia>
          <ixx>1e-5</ixx>
          <ixy>0</ixy>
          <ixz>0</ixz>
          <iyy>1e-5</iyy>
          <iyz>0</iyz>
          <izz>1e-5</izz>
        </inertia>
      </inertial>
      <visual name='propeller_visual'>
        <geometry>
          <mesh>
            <scale>1 1 1 </scale>
            <uri>model://autogyro/meshes/iris_prop_ccw.dae</uri>
          </mesh>
        </geometry>
        <material>
          <script>
            <name>Gazebo/Red</name>
            <uri>__default__</uri>
          </script>
        </material>
      </visual>
      <gravity>1</gravity>
      <velocity_decay/>
      <self_collide>0</self_collide>
    </link>

    <plugin name="motor" filename="libgazebo_simple_motor.so">
      <commandSubTopic>/gazebo/command/motor_speed</commandSubTopic>
      <motorNumber>4</motorNumber>
      <base_link>base_link</base_link>
      <force_pos>0.23 0 0.063</force_pos>
      <force_dir>0.99 0 -0.1</force_dir>
      <coef>0.01</coef>
    </plugin>


    <!--<plugin name='propeller_motor' filename='libgazebo_motor_model.so'>
      <robotNamespace></robotNamespace>
      <jointName>propeller_joint</jointName>
      <linkName>propeller</linkName>
      <turningDirection>cw</turningDirection>
      <timeConstantUp>0.0125</timeConstantUp>
      <timeConstantDown>0.025</timeConstantDown>
      <maxRotVelocity>3500</maxRotVelocity>
      <motorConstant>8.54858e-03</motorConstant>
      <momentConstant>0.01</momentConstant>
      <commandSubTopic>/gazebo/command/motor_speed</commandSubTopic>
      <motorNumber>0</motorNumber>
      <rotorDragCoefficient>8.06428e-01</rotorDragCoefficient>
      <rollingMomentCoefficient>1e-08</rollingMomentCoefficient>
      <motorSpeedPubTopic>/motor_speed/0</motorSpeedPubTopic>
      <rotorVelocitySlowdownSim>40</rotorVelocitySlowdownSim>
    </plugin>-->
<!--    <plugin name='propeller_motor' filename='libgazebo_motor_model.so'>
      <robotNamespace></robotNamespace>
      <jointName>propeller_joint</jointName>
      <linkName>propeller</linkName>
      <turningDirection>cw</turningDirection>
      <timeConstantUp>0.0125</timeConstantUp>
      <timeConstantDown>0.025</timeConstantDown>
      <maxRotVelocity>9500</maxRotVelocity>
      <motorConstant>8.54858e-05</motorConstant>
      <momentConstant>0.001</momentConstant>
      <commandSubTopic>/gazebo/command/motor_speed</commandSubTopic>
      <motorNumber>4</motorNumber>
      <rotorDragCoefficient>8.06428e-02</rotorDragCoefficient>
      <rollingMomentCoefficient>1e-6</rollingMomentCoefficient>
      <motorSpeedPubTopic>/motor_speed/0</motorSpeedPubTopic>
      <rotorVelocitySlowdownSim>50</rotorVelocitySlowdownSim>
    </plugin>-->

<!--============================================================== ROTOR ================================================-->
   <joint name='pitch_joint' type='revolute'>
      <child>pitch-dummylink</child>
      <parent>base_link</parent>
      <pose>0 0 0 0 0 0</pose>
      <axis>
        <xyz>0 1 0></xyz>
        <limit>          
          <lower>-0.349</lower>
          <upper>0.349</upper>
        </limit>
        <use_parent_model_frame>1</use_parent_model_frame>
      </axis>
      <physics>
        <ode>
            <cfm>0.000000</cfm>
            <erp>0.95000</erp>
        </ode>
      </physics>
    </joint>	

    <link name='pitch-dummylink'>
      <pose>0.0 0.0 0.4 0 0 0</pose>
	  <inertial>
        <pose>0 0 0 0 0 0</pose>
        <mass>0.02</mass>
        <inertia>
          <ixx>1e-3</ixx>
          <ixy>0</ixy>
          <ixz>0</ixz>
          <iyy>1e-3</iyy>
          <iyz>0</iyz>
          <izz>1e-3</izz>
        </inertia>
      </inertial>
    </link>

   <joint name='roll_joint' type='revolute'>
      <child>roll-dummylink</child>
      <parent>pitch-dummylink</parent>
      <pose>0 0 0 0 0 0</pose>
      <axis>
        <xyz>0.9781476007338057 0 0.20791169081775931</xyz>
        <limit>          
          <lower>-0.349</lower>
          <upper>0.349</upper>
        </limit>
        <use_parent_model_frame>1</use_parent_model_frame>
      </axis>
      <physics>
        <ode>
            <cfm>0.000000</cfm>
            <erp>0.95000</erp>
        </ode>
      </physics>
    </joint>

    <link name='roll-dummylink'>
      <pose>0.0 0.0 0.4 0 -0.20943951023931953 0</pose>
	  <inertial>
        <pose>0 0 0 0 0 0</pose>
        <mass>0.02</mass>
        <inertia>
          <ixx>1e-3</ixx>
          <ixy>0</ixy>
          <ixz>0</ixz>
          <iyy>1e-3</iyy>
          <iyz>0</iyz>
          <izz>1e-3</izz>
        </inertia>
      </inertial>
    </link>

    <joint name='spin_dummyjoint' type='revolute'>
      <child>rotor-center-link</child>
      <parent>roll-dummylink</parent>
      <pose>0 0 0 0 0 0</pose>
      <axis>
        <xyz> -0.20791169081775931 0 0.9781476007338057</xyz>
        <use_parent_model_frame>1</use_parent_model_frame>
      </axis>
      <physics>
        <ode>
            <cfm>0.000000</cfm>
            <erp>0.950000</erp>
        </ode>
      </physics>
    </joint>

    <plugin name="speed" filename="libgazebo_joint_speed_plugin.so">
      <joint>spin_dummyjoint</joint>
    </plugin>

    <link name='rotor-center-link'>
      <pose>0.0 0.0 0.4 0 -0.20943951023931953 0</pose>
	  <inertial>
        <pose>0 0 0 0 0 0</pose>
        <mass>0.05</mass>
        <inertia>
          <ixx>1e-03</ixx>
          <ixy>0</ixy>
          <ixz>0</ixz>
          <iyy>1e-03</iyy>
          <iyz>0</iyz>
          <izz>1e-03</izz>
        </inertia>
      </inertial>
     <visual name='rotor-center-visual'>
        <pose>0 0 0 0 0 0</pose>
        <geometry>
          <cylinder>
            <radius>0.01</radius>
            <length>0.01</length>
          </cylinder>
        </geometry>
     </visual>
    </link>

    <joint name='flap_right_joint' type='revolute'>
      <child>right-bladelink</child>
      <parent>rotor-center-link</parent>
      <pose>0 0.5 0 0 0 0</pose>-->
      <axis>
        <xyz>-0.9781476007338057 0.20791169081775931 0</xyz>
		<!--<use_parent_model_frame>1</use_parent_model_frame>-->
        <limit>          
          <lower>0.00</lower>
          <upper>0.35</upper>
        </limit>
      </axis>
      <physics>
        <ode>
            <cfm>0.000000</cfm>
            <erp>0.950000</erp>
        </ode>
      </physics>
    </joint>

	<!--<plugin name="left_spring" filename="libgazebo_joint_spring_plugin.so">
          <joint>flap_left_joint</joint>
          <parentPoint>0 0.1 0</parentPoint>
          <childPoint>0 -0.4 0</childPoint>
          <zero>0.0</zero>
          <k>1000</k>
	</plugin>-->

    <link name='right-bladelink'>
      <pose>0.0 -0.5 0.4 0 -0.20943951023931953 0</pose>
	  <inertial> 
        <mass>0.2</mass>
        <inertia>
          <ixx>0.016668333333333334</ixx>
          <ixy>0</ixy>
          <ixz>0</ixz>
          <iyy>6.166666666666666e-05</iyy>
          <iyz>0</iyz>
          <izz>0.00011999999999999999</izz>
        </inertia>
      </inertial>
	  <visual name='visual'>
		  <geometry>
		       <box>
          	      <size> 0.06 1.0 0.01</size>
               </box>
		 </geometry>
	 </visual>
     <collision name='link_collision'>
        <pose>0 0 0 0 0 0</pose>
        <geometry>
	       <box>
      	      <size> 0.06 1.0 0.01</size>
           </box>
        </geometry>
        <surface>
          <friction>
            <ode>
              <mu>0.1</mu>
              <mu2>0.1</mu2>
            </ode>
          </friction>
        </surface>
      </collision>
    </link>

    <joint name='flap_left_joint' type='revolute'>
      <child>left-bladelink</child>
      <parent>rotor-center-link</parent>
      <pose>0 0.5 0 0 0 0</pose>-->
      <axis>
        <xyz>-0.9781476007338057 0.20791169081775931 0</xyz>
		<!--<use_parent_model_frame>1</use_parent_model_frame>-->
        <limit>          
          <lower>0.00</lower>
          <upper>0.35</upper>
        </limit>
      </axis>
      <physics>
        <ode>
            <cfm>0.000000</cfm>
            <erp>0.950000</erp>
        </ode>
      </physics>
    </joint>

	<!--<plugin name="left_spring" filename="libgazebo_joint_spring_plugin.so">
          <joint>flap_left_joint</joint>
          <parentPoint>0 0.1 0</parentPoint>
          <childPoint>0 -0.4 0</childPoint>
          <zero>0.0</zero>
          <k>1000</k>
	</plugin>-->

    <link name='left-bladelink'>
      <pose>0.0 0.5 0.4 0 0.20943951023931953 3.141592653589793</pose>
	  <inertial> 
        <mass>0.2</mass>
        <inertia>
          <ixx>0.016668333333333334</ixx>
          <ixy>0</ixy>
          <ixz>0</ixz>
          <iyy>6.166666666666666e-05</iyy>
          <iyz>0</iyz>
          <izz>0.00011999999999999999</izz>
        </inertia>
      </inertial>
	  <visual name='visual'>
		  <geometry>
		       <box>
          	      <size> 0.06 1.0 0.01</size>
               </box>
		 </geometry>
	 </visual>
     <collision name='link_collision'>
        <pose>0 0 0 0 0 0</pose>
        <geometry>
	       <box>
      	      <size> 0.06 1.0 0.01</size>
           </box>
        </geometry>
        <surface>
          <friction>
            <ode>
              <mu>0.1</mu>
              <mu2>0.1</mu2>
            </ode>
          </friction>
        </surface>
      </collision>
    </link>

   <plugin name="left_rotorblade" filename="libgazebo_rotor_blade_plugin.so">
      <link>left-bladelink</link>
      <forward>1 0 0</forward>
      <upward> 0 0 1 </upward>
      <length> 1.0 </length>
      <width> 0.06 </width>
      <airDensity> 1.2041 </airDensity>
      <elementCount>50</elementCount>
   </plugin>

   <plugin name="right_rotorblade" filename="libgazebo_rotor_blade_plugin.so">
      <link>right-bladelink</link>
      <forward>1 0 0</forward>
      <upward> 0 0 1 </upward>
      <length> 1.0 </length>
      <width> 0.06 </width>
      <airDensity> 1.2041 </airDensity>
      <elementCount>50</elementCount>
   </plugin>

   
<!--========================================================= PX4Interface ================================================-->

    <plugin name='gazebo_imu_plugin' filename='libgazebo_imu_plugin.so'>
      <robotNamespace></robotNamespace>
      <linkName>imu_link</linkName>
      <imuTopic>/imu</imuTopic>
      <gyroscopeNoiseDensity>0.0003394</gyroscopeNoiseDensity>
      <gyroscopeRandomWalk>3.8785e-05</gyroscopeRandomWalk>
      <gyroscopeBiasCorrelationTime>1000.0</gyroscopeBiasCorrelationTime>
      <gyroscopeTurnOnBiasSigma>0.0087</gyroscopeTurnOnBiasSigma>
      <accelerometerNoiseDensity>0.004</accelerometerNoiseDensity>
      <accelerometerRandomWalk>0.006</accelerometerRandomWalk>
      <accelerometerBiasCorrelationTime>300.0</accelerometerBiasCorrelationTime>
      <accelerometerTurnOnBiasSigma>0.196</accelerometerTurnOnBiasSigma>
    </plugin>
    <plugin name="gps_plugin" filename="libgazebo_gps_plugin.so">
        <robotNamespace></robotNamespace>
        <gpsNoise>true</gpsNoise>
    </plugin>

    <plugin name='mavlink_interface' filename='libgazebo_mavlink_interface.so'>
      <robotNamespace></robotNamespace>
      <imuSubTopic>/imu</imuSubTopic>
      <gpsSubTopic>/gps</gpsSubTopic>
      <mavlink_addr>INADDR_ANY</mavlink_addr>
      <mavlink_udp_port>14560</mavlink_udp_port>
      <serialEnabled>false</serialEnabled>
      <serialDevice>/dev/ttyACM0</serialDevice>
      <baudRate>921600</baudRate>
      <qgc_addr>INADDR_ANY</qgc_addr>
      <qgc_udp_port>14550</qgc_udp_port>
      <hil_mode>false</hil_mode>
      <hil_state_level>false</hil_state_level>
      <motorSpeedCommandPubTopic>/gazebo/command/motor_speed</motorSpeedCommandPubTopic>
      <control_channels>

   <channel name="propeller">
      <input_index>4</input_index>
      <input_offset>0</input_offset>
      <input_scaling>3500</input_scaling>
      <zero_position_disarmed>0</zero_position_disarmed>
      <zero_position_armed>0</zero_position_armed>
      <joint_control_type>velocity</joint_control_type>
      <joint_name>propeller_joint</joint_name>
    </channel>

    <!-- manuální ovládání placičky-->

    <channel name="roll_channel">
          <input_index>2</input_index>
          <input_offset>0</input_offset>
          <input_scaling>0.09</input_scaling>
          <gztopic>/rotor_roll_cmd</gztopic>
          <zero_position_disarmed>0</zero_position_disarmed>
          <zero_position_armed>0</zero_position_armed>
          <joint_control_type>position</joint_control_type>
          <joint_name>roll_joint</joint_name>
          <joint_control_pid>
            <p>100</p>
            <i>0</i>
            <d>0.1</d>
            <iMax>0</iMax>
            <iMin>0</iMin>
            <cmdMax>100</cmdMax>
            <cmdMin>-100</cmdMin>
          </joint_control_pid>
        </channel>

        <channel name="pitch_channel">
          <input_index>3</input_index>
          <input_offset>0.0</input_offset>
          <input_scaling>0.09</input_scaling>
          <gztopic>/rotor_pitch_cmd</gztopic>
          <zero_position_disarmed>0</zero_position_disarmed>
          <zero_position_armed>0</zero_position_armed>
          <joint_control_type>position</joint_control_type>
          <joint_name>pitch_joint</joint_name>
          <joint_control_pid>
            <p>100</p>
            <i>0</i>
            <d>0.1</d>
            <iMax>0</iMax>
            <iMin>0</iMin>
            <cmdMax>100</cmdMax>
            <cmdMin>-100</cmdMin>
          </joint_control_pid>
        </channel>

        <!-- ocas-->

        <channel name="left_rudder_channel">
          <input_index>0</input_index>
          <input_offset>0</input_offset>
          <input_scaling>1</input_scaling>
          <zero_position_disarmed>0</zero_position_disarmed>
          <zero_position_armed>0</zero_position_armed>
		  <!--<joint_control_type>position_kinematic</joint_control_type>-->
          <joint_control_type>position</joint_control_type>
          <joint_control_pid>
            <p>10</p>
            <i>0</i>
            <d>0.05</d>
            <iMax>0</iMax>
            <iMin>0</iMin>
            <cmdMax>50</cmdMax>
            <cmdMin>-50</cmdMin>
          </joint_control_pid>
          <joint_name>left_rudder_joint</joint_name>
        </channel>

        <channel name="right_rudder_channel">
          <input_index>1</input_index>
          <input_offset>0</input_offset>
          <input_scaling>1</input_scaling>
          <zero_position_disarmed>0</zero_position_disarmed>
          <zero_position_armed>0</zero_position_armed>
		 <!-- <joint_control_type>position_kinematic</joint_control_type>-->
          <joint_control_type>position</joint_control_type>
          <joint_control_pid>
            <p>10</p>
            <i>0</i>
            <d>0.05</d>
            <iMax>0</iMax>
            <iMin>0</iMin>
            <cmdMax>50</cmdMax>
            <cmdMin>-50</cmdMin>
          </joint_control_pid>
          <joint_name>right_rudder_joint</joint_name>
        </channel>

      </control_channels>
    </plugin>
    <static>0</static>
  </model>
</sdf>
